Traceback (most recent call last):
  File "/Users/ckim/miniconda3/envs/astro-tigress-new/lib/python3.11/site-packages/nbclient/client.py", line 778, in _async_poll_for_reply
    msg = await ensure_async(self.kc.shell_channel.get_msg(timeout=new_timeout))
          ^^^^^^^^^^^^^^^^^^^^^^^^^^^^^^^^^^^^^^^^^^^^^^^^^^^^^^^^^^^^^^^^^^^^^^
  File "/Users/ckim/miniconda3/envs/astro-tigress-new/lib/python3.11/site-packages/jupyter_core/utils/__init__.py", line 182, in ensure_async
    result = await obj
             ^^^^^^^^^
  File "/Users/ckim/miniconda3/envs/astro-tigress-new/lib/python3.11/site-packages/jupyter_client/channels.py", line 315, in get_msg
    raise Empty
_queue.Empty

During handling of the above exception, another exception occurred:

Traceback (most recent call last):
  File "/Users/ckim/miniconda3/envs/astro-tigress-new/lib/python3.11/site-packages/jupyter_cache/executors/utils.py", line 58, in single_nb_execution
    executenb(
  File "/Users/ckim/miniconda3/envs/astro-tigress-new/lib/python3.11/site-packages/nbclient/client.py", line 1305, in execute
    return NotebookClient(nb=nb, resources=resources, km=km, **kwargs).execute()
           ^^^^^^^^^^^^^^^^^^^^^^^^^^^^^^^^^^^^^^^^^^^^^^^^^^^^^^^^^^^^^^^^^^^^^
  File "/Users/ckim/miniconda3/envs/astro-tigress-new/lib/python3.11/site-packages/jupyter_core/utils/__init__.py", line 166, in wrapped
    return loop.run_until_complete(inner)
           ^^^^^^^^^^^^^^^^^^^^^^^^^^^^^^
  File "/Users/ckim/miniconda3/envs/astro-tigress-new/lib/python3.11/asyncio/base_events.py", line 653, in run_until_complete
    return future.result()
           ^^^^^^^^^^^^^^^
  File "/Users/ckim/miniconda3/envs/astro-tigress-new/lib/python3.11/site-packages/nbclient/client.py", line 705, in async_execute
    await self.async_execute_cell(
  File "/Users/ckim/miniconda3/envs/astro-tigress-new/lib/python3.11/site-packages/nbclient/client.py", line 1001, in async_execute_cell
    exec_reply = await self.task_poll_for_reply
                 ^^^^^^^^^^^^^^^^^^^^^^^^^^^^^^
  File "/Users/ckim/miniconda3/envs/astro-tigress-new/lib/python3.11/site-packages/nbclient/client.py", line 802, in _async_poll_for_reply
    error_on_timeout_execute_reply = await self._async_handle_timeout(timeout, cell)
                                     ^^^^^^^^^^^^^^^^^^^^^^^^^^^^^^^^^^^^^^^^^^^^^^^
  File "/Users/ckim/miniconda3/envs/astro-tigress-new/lib/python3.11/site-packages/nbclient/client.py", line 852, in _async_handle_timeout
    raise CellTimeoutError.error_from_timeout_and_cell(
nbclient.exceptions.CellTimeoutError: A cell timed out while it was being executed, after 30 seconds.
The message was: Cell execution timed out.
Here is a preview of the cell contents:
-------------------
#load the CO line dataset for the snapshot ivtk=290
model.load(290, dataset="CO_lines", iline=1) #CO(J=1-0)
model.load(290, dataset="CO_lines", iline=2) #CO(J=2-1)
-------------------

